Workbook

Sheet HOME
A1: Portfolio Content Hub
A2: Edit the workbook from a single control center, then sync the site.
A3: MASTER WORKBOOK | LAST SYNC 2026-10-25 20:55:30 UTC | CTRL+CLICK LINKS TO NAVIGATE
A4: Use the cards below for primary editing, the workflow panel for the sync cycle, and the grouped panels at the bottom for advanced sheets.
A5: PROFILE | F5: PROJECTS | K5: TESTIMONIALS
A6: Identity and about copy | F6: 7 showcased projects | K6: 17 client reviews
A8: 1 main editor surface | D8: Open sheet | F8: Cards, media wiring, stack, and ordering | I8: Open sheet | K8: Featured order, sources, and avatar assets | N8: Open sheet
A10: HERO | F10: CONTACT | K10: ASSETS
A11: 2 metadata rows | F11: 4 social links | K11: 50 registered assets
A13: Landing copy, labels, and CTA wiring | D13: Open sheet | F13: Form labels, metadata, and footer copy | I13: Open sheet | K13: Sources, resolved paths, usage, and previews | N13: Open sheet
A16: WORKFLOW | I16: COMMON EDITS
A17: 1. Jump into the section you want to edit. 2. Make changes inside the shaded input area. 3. Run npm run content:check for validation only. 4. Run npm run content:sync to refresh the workbook and runtime JSON. 5. Run npm run build when you want a full site verification. | I17: Fast entry points for the sheets you will touch most often.
I18: Workbook Guide
I19: Profile
I20: Projects
I21: Testimonials
A23: ADVANCED SHEETS
A24: SITE FRAME | D24: ABOUT | G24: TERMINAL | J24: RELATIONS | M24: SOURCES
A25: Navigation shell | D25: Bio and hero support | G25: Command UX copy | J25: Skills and project links | M25: Proof and footer
A26: Navigation Config | D26: About Bio | G26: Terminal | J26: Skill Categories | M26: Testimonial Sources
A27: Navigation | D27: About Stats | G27: Terminal Lines | J27: Skill Items | M27: Contact Social
A28: Section Headers | D28: Hero Metadata | G28: Terminal Capabilities | J28: Project Stack | M28: Contact Metadata
J29: Project Architecture | M29: Footer

Sheet README
A1: Workbook Guide
A2: Editing rules, shortcuts, and the quickest path to each content area.
A3: GUIDE SHEET | LAST SYNC 2026-10-25 20:55:30 UTC | START FROM HOME FOR THE FASTEST FLOW
A4: Back to HOME | C4: Use the quick links below for the main editing areas. Open HOME if you need the full grouped navigation map.
A5: Profile | C5: Projects | E5: Testimonials | G5: Assets | I5: Preview
A7: SOURCE OF TRUTH | E7: COMMAND FLOW | I7: LINK BEHAVIOR
A8: Edit only src/data/content/portfolio-master.xlsx. The website consumes generated JSON, but the workbook is the only place you should author content. | E8: content:init -> one-time bootstrap only content:check -> validation without publishing content:sync -> rebuild workbook UI and runtime JSON build -> final site verification | I8: CTRL+CLICK linked ids to jump between sheets. assetId, project_id, sourceKey, and preview links are wired automatically every sync.
A13: ADD A PROJECT | E13: ADD A TESTIMONIAL | I13: ASSET MODES
A14: 1. Add a row in PROJECTS. 2. Add stack rows in PROJECT_STACK. 3. Add architecture rows in PROJECT_ARCH. 4. Point media fields to asset ids from ASSETS. 5. Run content:sync. | E14: 1. Add a row in TESTIMONIALS. 2. Reuse or add a source preset in TESTIMONIAL_SOURCES. 3. Set featured = TRUE to show it on the site. 4. Use featuredOrder to control visible order and highlighted = TRUE to visually emphasize it. 5. Run content:sync. | I14: existing_public -> file already lives inside public/ import_local -> copy a local file into public/ external_url -> point directly to a remote asset
A20: PRIMARY EDIT SURFACES | G20: ADVANCED SHEETS
A21: Profile | G21: Navigation Config
A22: Hero | G22: Navigation
A23: Projects | G23: About Bio
A24: Testimonials | G24: About Stats
A25: Contact | G25: Hero Metadata
A26: Assets | G26: Terminal
A27: Asset Preview Index | G27: Terminal Lines
G28: Open HOME for the full grouped list of advanced sheets.

Sheet _LOOKUPS
A1: booleanValues | B1: starValues | C1: assetKinds | D1: assetModes | E1: demoTypes | F1: iconFits | G1: terminalColors | H1: terminalGroups | I1: skillColors | J1: skillIcons | K1: socialIcons | L1: sourceKeys | M1: projectIds | N1: assetIds | O1: categoryIds | P1: sectionIds
A2: TRUE | B2: 1 | C2: image | D2: existing_public | E2: video | F2: auto | G2: electric-green | H2: initial | I2: electric-green | J2: Cpu | K2: Github | L2: fiverr | M2: 1 | N2: profile-avatar | O2: core-development | P2: about
A3: FALSE | B3: 2 | C3: video | D3: import_local | E3: image | F3: cover | G3: electric-cyan | H3: greeting | I3: electric-cyan | J3: Brain | K3: Linkedin | L3: direct | M3: 2 | N3: project-1-video | O3: ai-vision-workflows | P3: projects
B4: 3 | C4: icon | D4: external_url | E4: youtube | G4: white | J4: Layers | K4: Twitter | M4: 3 | N4: project-1-thumbnail | O4: frontend-interactive-systems | P4: tech
B5: 4 | C5: other | G5: gray | J5: Globe | K5: Upwork | M5: 4 | N5: project-1-icon | O5: infra-delivery | P5: architect
B6: 5 | M6: 5 | N6: project-2-video | P6: console
M7: 6 | N7: project-2-thumbnail
M8: 7 | N8: project-2-icon
N9: project-3-video
N10: project-3-thumbnail
N11: project-3-icon
N12: project-4-video
N13: project-4-thumbnail
N14: project-4-icon
N15: project-5-video
N16: project-5-thumbnail
N17: project-5-icon
N18: testimonial-client3
N19: testimonial-client2
N20: testimonial-client1
... N51: datacraft-video

Sheet PROFILE
A1: Profile
A2: Identity, bio headline, social links, and testimonial section copy.
A3: PRIMARY EDIT SURFACE | LAST SYNC 2026-10-25 20:55:30 UTC
A4: Back to HOME | C4: Guide | E4: Prev: Workbook Guide | G4: Next: Hero | I4: About Bio | K4: About Stats | M4: Assets
A5: Primary editing surface. Keep changes inside the table area and use linked ids to move between related records.
A6: Required | C6: Optional | E6: Generated | G6: Linked
A7: Editable data starts below. Use dropdown cells where present, and CTRL+CLICK linked ids to jump between related sheets.
A8: name | B8: role | C8: tagline | D8: avatarAssetId | E8: aboutTitle | F8: featuredProjectId | G8: featuredProjectLabel | H8: philosophyLabel | I8: philosophyQuote | J8: github | K8: linkedin | L8: testimonialsTitle | M8: testimonialsSubtitle | N8: rowStatus
A9: Alberto Medina Garcia | B9: Computer Engineering student & software developer | C9: I build reliable products, automation workflows, and AI systems with clear product thinking. | D9: profile-avatar | E9: From game development to everyday tools. | F9: 7 | G9: An independent product | H9: Working with AI | I9: AI helps me move faster. I review the code, test the result and take responsibility for what ships. | J9: https://github.com/Albjav12345 | K9: https://www.linkedin.com/in/alberto-medina-dev/ | L9: Verified Client Feedback | M9: Real feedback from completed Fiverr orders. Client handles and avatars are anonymized for privacy. | N9: READY

Sheet HERO
A1: Hero
A2: Landing copy, calls to action, and top-level positioning.
A3: PRIMARY EDIT SURFACE | LAST SYNC 2026-10-25 20:55:30 UTC
A4: Back to HOME | C4: Guide | E4: Prev: Profile | G4: Next: Projects | I4: Hero Metadata
A5: Navigation
A6: Required | B6: Optional | C6: Generated | D6: Linked
A7: Editable data starts below. Use dropdown cells where present, and CTRL+CLICK linked ids to jump between related sheets.
A8: priorityLabel | B8: titleWhite | C8: titleGreen | D8: handle | E8: description | F8: buttonTerminal | G8: buttonCv | H8: buttonCvPending | I8: buttonCvHref | J8: rowStatus
A9: FULL-STACK SYSTEMS / AUTOMATION / AI | B9: ALBERTO | C9: MEDINA | D9: @Albjav12345 | E9: I design and ship full-stack products, automation workflows, and AI systems—from polished interfaces to reliable backend operations. | F9: ACCESS_TERMINAL | G9: DOWNLOAD_CV.PDF | H9: CV_PENDING | I9: /Alberto_Medina_CV_2026.pdf | J9: READY

Sheet PROJECTS
A1: Projects
A2: Main project cards, value story, media wiring, and ordering.
A3: PRIMARY EDIT SURFACE | LAST SYNC 2026-10-25 20:55:30 UTC
A4: Back to HOME | C4: Guide | E4: Prev: Hero | G4: Next: Testimonials | I4: Project Stack | K4: Project Architecture | M4: Assets
A5: Primary editing surface. Keep changes inside the table area and use linked ids to move between related records.
A6: Required | C6: Optional | E6: Generated | G6: Linked
A7: Editable data starts below. Use dropdown cells where present, and CTRL+CLICK linked ids to jump between related sheets.
A8: id | B8: title | C8: subtitle | D8: problem | E8: solution | F8: githubLink | G8: itchLink | H8: assetStoreLink | I8: assetStoreComingSoon | J8: gallerySize | K8: cardLabel | L8: galleryAssetIds | M8: demoEmbedUrl | N8: demoType | O8: videoAssetId | P8: thumbnailAssetId | Q8: iconAssetId | R8: iconFit | S8: iconScale | T8: order | U8: enabled | V8: rowStatus
A9: 1 | B9: Unity Interface Systems | C9: High-Fidelity Real-Time UX | D9: A lot of developers can build tools. Far fewer can build custom interfaces that feel intentional inside a real-time engine. | E9: I built polished Unity interfaces and supporting shader work to show that I can design and implement unusual UI systems, not just standard app screens. | F9: https://github.com/Albjav12345/unity-interfaces | I9: FALSE | N9: video | O9: project-1-video | P9: project-1-thumbnail | Q9: project-1-icon | S9: 1.3 | T9: 2 | U9: TRUE | V9: READY
A10: 2 | B10: Smart Inbox Manager | C10: Autonomous Corporate Email Triage | D10: Sales and partnership inboxes become noisy fast, and teams lose time triaging the same messages manually. | E10: I built a full-stack AI workflow that classifies incoming emails, drafts first replies, and keeps a human in control where it matters. | F10: https://github.com/Albjav12345/zero_touch_email_bot | I10: FALSE | J10: wide | N10: video | O10: project-2-video | P10: project-2-thumbnail | Q10: project-2-icon | R10: auto | S10: 1.25 | T10: 4 | U10: TRUE | V10: READY
A11: 3 | B11: Padel Booking Platform | C11: Live Availability & Conflict-Free Booking | D11: Manual booking created conflicts, stale availability, and too much back-and-forth for users. | E11: I shipped a serverless PWA with real-time sync and validation so availability updates instantly and booking conflicts are resolved at the system level. | F11: https://github.com/Albjav12345/padel-sync | I11: FALSE | N11: video | O11: project-3-video | P11: project-3-thumbnail | Q11: project-3-icon | T11: 3 | U11: TRUE | V11: READY
A12: 4 | B12: Twitch Live Analytics | C12: Real-time Streamer Detection | D12: Finding live streamers in Fortnite lobbies manually was slow, repetitive, and easy to get wrong. | E12: I automated the workflow with screen capture, OCR, and Twitch API checks so detection became fast, repeatable, and much easier to monitor. | F12: https://github.com/Albjav12345/Fortnite-Lobby-Stream-Finder | I12: FALSE | N12: video | O12: project-4-video | P12: project-4-thumbnail | Q12: project-4-icon | S12: 1.3 | T12: 5 | U12: TRUE | V12: READY
A13: 5 | B13: USB Exfiltration Tool | C13: Controlled Security Research & Endpoint Automation | D13: Authorized endpoint collection can fail because of file locks, manual steps, and inconsistent evidence handling during controlled security exercises. | E13: I built a Windows-based acquisition workflow for authorized lab and red-team scenarios, combining native system polling, explicit operator controls, and low-friction evidence collection. | F13: https://github.com/Albjav12345/Automated-USB-Exfiltration | I13: FALSE | J13: half | N13: video | O13: project-5-video | P13: project-5-thumbnail | Q13: project-5-icon | R13: auto | T13: 6 | U13: TRUE | V13: READY
A14: 6 | B14: Remote PC Bridge | C14: ESP32 Wake-on-LAN & Remote Streaming Diagnostics | D14: A home PC that is powered off cannot be reached through remote streaming, and failures across the wake and connection path are hard to pinpoint. | E14: I built a Windows controller and ESP32 firmware that wake the PC over the home network, check each connection stage, and launch Moonlight when the desktop is ready. | F14: https://github.com/Albjav12345/remote-pc-bridge | I14: FALSE | J14: half | N14: video | O14: project-6-video | P14: project-6-thumbnail | Q14: project-6-icon | R14: auto | S14: 1 | T14: 7 | U14: TRUE | V14: READY
A15: 7 | B15: DataCraft | C15: Visual JSON tools for Unity | D15: Game data, API responses and player saves often live in scattered files and custom scripts. Unity teams need a visual workflow with a reliable path to gameplay. | E15: I built a commercial Unity asset for typed templates, linked instances, JSON/CSV transfer, API-to-C# generation and local saves. Validation and explicit catalog publishing keep editable drafts, gameplay data and player progress separate. | G15: https://albjav12345.itch.io/datacraft | I15: TRUE | J15: feature | K15: Independent Unity asset | L15: datacraft-gallery-1|datacraft-gallery-2|datacraft-gallery-3|datacraft-gallery-4|datacraft-gallery-5|datacraft-gallery-6|datacraft-gallery-7|datacraft-gallery-8 | M15: https://www.youtube-nocookie.com/embed/Uqpto9OyuA0 | N15: video | O15: datacraft-video | P15: datacraft-cover | Q15: datacraft-icon | R15: auto | S15: 1 | T15: 1 | U15: TRUE | V15: READY

Sheet TESTIMONIALS
A1: Testimonials
A2: Review copy, star rating, featured placement, and avatar assets.
A3: PRIMARY EDIT SURFACE | LAST SYNC 2026-10-25 20:55:30 UTC
A4: Back to HOME | C4: Guide | E4: Prev: Projects | G4: Next: Contact | I4: Testimonial Sources | K4: Assets
A5: Primary editing surface. Keep changes inside the table area and use linked ids to move between related records.
A6: Required | C6: Optional | E6: Generated | G6: Linked
A7: Editable data starts below. Use dropdown cells where present, and CTRL+CLICK linked ids to jump between related sheets.
A8: id | B8: sourceKey | C8: labelOverride | D8: clientName | E8: clientType | F8: serviceOverride | G8: review | H8: starRating | I8: gigTitle | J8: createdAt | K8: avatarAssetId | L8: featured | M8: featuredOrder | N8: highlighted | O8: order | P8: rowStatus
A9: unity-progress-communication | B9: fiverr | E9: Indie Founder / First Delivery | F9: Unity UI / Editor Tools | G9: It's been a pleasure working with Alberto. He has been great at communicating the the progress of the project, sharing updates and asking for feedback to ensure requirements where meet. He has been pleasant to work with and delivered a very professional job. Will definitely recommend for UI Unity projects and hope to work with again. | H9: 2 | I9: create professional unity editor windows or game uis with uxml | J9: 2024-06-16T19:22:08Z | K9: testimonial-client8 | L9: FALSE | N9: FALSE | O9: 1 | P9: LIBRARY
A10: unity-fast-delivery | B10: fiverr | E10: Solo Developer / Tight Deadline | F10: Unity UI / Editor Tools | G10: Very professional job. Sent timely updates during the project. Asked for clarification when needed and delivered sooner than we originally agreed. | H10: 3 | I10: create professional unity editor windows or game uis with uxml | J10: 2024-07-02T16:25:00Z | K10: testimonial-client13 | L10: TRUE | M10: 3 | N10: FALSE | O10: 2 | P10: FEATURED
A11: unity-communication | B11: fiverr | E11: Indie Buyer / Feedback Loop | F11: Unity UI / Editor Tools | G11: Great work and great communication. | H11: 4 | I11: create professional unity editor windows or game uis with uxml | J11: 2024-07-05T20:42:58Z | K11: testimonial-client14 | L11: TRUE | M11: 5 | N11: FALSE | O11: 3 | P11: FEATURED
A12: unity-great-work | B12: fiverr | E12: Game Creator / Small Sprint | F12: Unity UI / Editor Tools | G12: Great work! | H12: 5 | I12: create professional unity editor windows or game uis with uxml | J12: 2024-07-21T14:05:57Z | K12: testimonial-client2 | L12: FALSE | N12: FALSE | O12: 4 | P12: LIBRARY
A13: unity-complex-ownership | B13: fiverr | E13: Indie Studio / Systems Owner | F13: Unity UI / Game Systems | G13: Much better than expected. He did a good job with somewhat complex tasks and overcame them quite well. He has not only limited himself to the main stuff, but contributed with ideas and helped me in other aspects of the project. He's done his work against the clock, with commitment and eagerness to do a well done job, so I hope we could work soon again together! | H13: 5 | I13: create professional unity game uis or editor windows with ui toolkit | J13: 2024-07-29T16:57:35Z | K13: testimonial-client12 | L13: TRUE | M13: 1 | N13: TRUE | O13: 5 | P13: FEATURED / HIGHLIGHTED
A14: unity-repeat-client | B14: fiverr | E14: Returning Buyer / Active Build | F14: Unity UI / Game Systems | G14: Great work as always | H14: 5 | I14: create professional unity game uis or editor windows with ui toolkit | J14: 2024-09-27T19:47:17Z | K14: testimonial-client15 | L14: TRUE | M14: 7 | N14: FALSE | O14: 6 | P14: FEATURED
A15: automation-seo-detail | B15: fiverr | E15: Local Brand / Image Library | F15: Automation / Metadata Workflow | G15: I had a fantastic experience working with this professional. The attention to detail in optimizing my images for SEO, including the meticulous work with geotags, keywords, and descriptions, was exceptional. Every instruction I provided was followed precisely, and the final files were delivered in perfect order. Highly recommended for anyone looking to enhance their visual content for better search engine performance. I will definitely use their services again! | H15: 5 | I15: edit photos and videos metadata for easy gallery managing | J15: 2024-11-07T20:02:11Z | K15: testimonial-client5 | L15: FALSE | N15: FALSE | O15: 7 | P15: LIBRARY
A16: automation-exceeded-expectations | B16: fiverr | E16: Agency Owner / Client Handoff | F16: Automation / SEO Workflow | G16: Alberto Medina truly exceeded my expectations with his attention to detail and professionalism. Working with him was a pleasure; he was cooperative, went above and beyond, and remained polite throughout. Highly recommend! 👏 | H16: 5 | I16: edit photos and videos metadata for gallery and seo managing | J16: 2024-11-08T22:07:56Z | K16: testimonial-pack-leaf | L16: TRUE | M16: 2 | N16: TRUE | O16: 8 | P16: FEATURED / HIGHLIGHTED
A17: automation-gallery-spanish | B17: fiverr | E17: Photo Seller / Gallery Sorting | F17: Automation / SEO Workflow | G17: Muy satisfecho con el servicio. Este vendedor hizo un excelente trabajo ajustando los metadatos de 30 fotos para que se ordenen correctamente en mi galería. Fue rápido y eficiente, justo lo que necesitaba. Estaré encantado de volver a trabajar con el en un futuro! | H17: 5 | I17: edit photos and videos metadata for gallery and seo managing | J17: 2024-11-09T18:29:07Z | K17: testimonial-client8 | L17: FALSE | N17: FALSE | O17: 9 | P17: LIBRARY
A18: automation-fiverr-credit | B18: fiverr | E18: Content Team / Process Cleanup | F18: Automation / SEO Workflow | G18: Alberto is a real credit to Fiverr. Exceptional talent. Highly recommended. Hope to work with him again. | H18: 5 | I18: edit photos and videos metadata for gallery and seo managing | J18: 2024-11-19T14:13:23Z | K18: testimonial-pack-av | L18: TRUE | M18: 4 | N18: TRUE | O18: 10 | P18: FEATURED / HIGHLIGHTED
A19: automation-outstanding-work | B19: fiverr | E19: Shop Owner / Batch Delivery | F19: Automation / SEO Workflow | G19: Thank you very much, I am surprised by the very, very good work, it exceeded my expectations. I will let Alberto do more projects. Thanks again for your outstanding work! | H19: 5 | I19: edit photos and videos metadata for gallery and seo managing | J19: 2024-12-08T08:55:41Z | K19: testimonial-client3 | L19: FALSE | N19: FALSE | O19: 11 | P19: LIBRARY
A20: automation-communication-timelines | B20: fiverr | E20: SEO Consultant / Revision Round | F20: Automation / SEO Workflow | G20: Alberto is exceptional, quick understanding, excellent communication and meeting expectations and timelines. He did any revisions needed with no hassle. Highly recommended. | H20: 5 | I20: edit photos and videos metadata for gallery and seo managing | J20: 2024-12-12T19:03:03Z | K20: testimonial-pack-signature | L20: TRUE | M20: 6 | N20: TRUE | O20: 12 | P20: FEATURED / HIGHLIGHTED
A21: automation-wonderful-details | B21: fiverr | E21: Media Archive / Detail Pass | F21: Automation / SEO Workflow | G21: Wonderful details | H21: 5 | I21: edit photos and videos metadata for gallery and seo managing | J21: 2024-12-15T18:18:51Z | K21: testimonial-client4 | L21: FALSE | N21: FALSE | O21: 13 | P21: LIBRARY
A22: automation-vigor | B22: fiverr | E22: Ops Support / Bulk Task | F22: Automation / SEO Workflow | G22: Handled the task with vigor | H22: 5 | I22: edit photos and videos metadata for seo and gallery managing | J22: 2025-01-06T09:56:00Z | K22: testimonial-client7 | L22: FALSE | N22: FALSE | O22: 14 | P22: LIBRARY
A23: automation-fast-turnaround | B23: fiverr | E23: Urgent Order / Quick Turnaround | F23: Automation / SEO Workflow | G23: Good job and fast | H23: 5 | I23: edit photos and videos metadata for seo and gallery managing | J23: 2025-01-06T17:58:51Z | K23: testimonial-client6 | L23: FALSE | N23: FALSE | O23: 15 | P23: LIBRARY
A24: automation-highly-recommend | B24: fiverr | E24: Returning Buyer / Quick Fix | F24: Automation / SEO Workflow | G24: He's great. I highly recommend | H24: 5 | I24: edit photos and videos metadata for seo and gallery managing | J24: 2025-01-30T18:59:30Z | K24: testimonial-client11 | L24: FALSE | N24: FALSE | O24: 16 | P24: LIBRARY
A25: automation-nice-guy | B25: fiverr | E25: Solo Operator / One-Off Request | F25: Automation / SEO Workflow | G25: Nice guy he does his work good! Go check him out guys | H25: 5 | I25: edit photos and videos metadata for seo and gallery managing | J25: 2025-01-31T10:10:16Z | K25: testimonial-client1 | L25: FALSE | N25: FALSE | O25: 17 | P25: LIBRARY

Sheet CONTACT
A1: Contact
A2: Primary contact copy, form labels, response states, and endpoint info.
A3: PRIMARY EDIT SURFACE | LAST SYNC 2026-10-25 20:55:30 UTC
A4: Back to HOME | C4: Guide | E4: Prev: Testimonials | G4: Next: Assets | I4: Contact Social | K4: Contact Metadata | M4: Footer
A5: Primary editing surface. Keep changes inside the table area and use linked ids to move between related records.
A6: Required | C6: Optional | E6: Generated | G6: Linked
A7: Editable data starts below. Use dropdown cells where present, and CTRL+CLICK linked ids to jump between related sheets.
A8: label | B8: titleLine1 | C8: titleLine2 | D8: description | E8: endpointLabel | F8: email | G8: formNameLabel | H8: formNamePlaceholder | I8: formEmailLabel | J8: formEmailPlaceholder | K8: formMessageLabel | L8: formMessagePlaceholder | M8: submitIdle | N8: submitSending | O8: submitSuccess | P8: submitError | Q8: rowStatus
A9: Direct Communication | B9: READY TO | C9: BUILD. | D9: For product engineering roles, freelance builds, or systems work, share the context and the outcome you need. We can scope the next step from there. | E9: Primary_Contact | F9: amedina.amg.dev@gmail.com | G9: USER_IDENTITY.src | H9: Enter your name... | I9: RETURN_PATH.void | J9: your@email.com | K9: DATA_PAYLOAD.txt | L9: Describe your project, system, or idea... | M9: EXECUTE_TRANSMISSION | N9: TRANSMITTING... | O9: SUCCESS_CONFIRMED | P9: TRANSMISSION_ERROR | Q9: READY

Sheet ASSETS
A1: Assets
A2: Central asset registry. For existing_public assets, edit sourceValue as the canonical path; targetPublicPath is mainly for import_local copies.
A3: PRIMARY EDIT SURFACE | LAST SYNC 2026-10-25 20:55:30 UTC
A4: Back to HOME | C4: Guide | E4: Prev: Contact | G4: Next: Asset Preview Index | I4: Asset Preview Index | K4: Projects | M4: Testimonials
A5: Primary editing surface. Keep changes inside the table area and use linked ids to move between related records.
A6: Required | C6: Optional | E6: Generated | G6: Linked
A7: Editable data starts below. Use dropdown cells where present, and CTRL+CLICK linked ids to jump between related sheets.
A8: assetId | B8: kind | C8: mode | D8: sourceValue | E8: targetPublicPath | F8: alt | G8: notes | H8: enabled | I8: resolvedUrl | J8: openSource | K8: openResolved | L8: usedBy | M8: previewLink | N8: rowStatus
A9: profile-avatar | B9: image | C9: existing_public | D9: /assets/alberto.webp | E9: /assets/alberto.webp | F9: Alberto Medina Garcia avatar | G9: Main profile avatar | H9: TRUE | I9: =IF($A9="","",IF(UPPER($H9)<>"TRUE","",IF($C9="import_local",IF($E9<>"",$E9,""),IF($C9="external_url",$D9,IF(IF($D9<>"",$D9,$E9)<>"",IF($D9<>"",$D9,$E9),""))))) -> /assets/alberto.webp | J9: =IF($A9="","",IF(UPPER($H9)<>"TRUE","Disabled",HYPERLINK("http://127.0.0.1:5173/__dev/asset-source"&"?assetId="&ENCODEURL($A9)&"&sig="&ENCODEURL($B9&"|"&$C9&"|"&$D9&"|"&$E9&"|"&$H9),"Open source"))) -> Open source | K9: =IF($A9="","",IF(OR(UPPER($H9)<>"TRUE",$I9=""),"Unavailable",HYPERLINK("http://127.0.0.1:5173/__dev/asset-resolved"&"?assetId="&ENCODEURL($A9)&"&sig="&ENCODEURL($B9&"|"&$C9&"|"&$D9&"|"&$E9&"|"&$H9),"Open resolved"))) -> Open resolved | L9: Profile avatar | M9: =IF($A9="","",HYPERLINK("#'ASSET_PREVIEW'!A9","Open preview")) -> Open preview | N9: =IF($A9="","",IF(UPPER($H9)<>"TRUE","DISABLED",IF($C9="external_url",IF(OR(LEFT(LOWER($D9),7)="http://",LEFT(LOWER($D9),8)="https://"),"READY -> "&$I9,"NEEDS HTTP URL"),IF($C9="import_local",IF($D9="","NEEDS SOURCE FILE",IF($E9="","NEEDS TARGET PATH","READY -> "&$I9)),IF($C9="existing_public",IF(IF($D9<>"",$D9,$E9)<>"","READY -> "&$I9,"NEEDS PUBLIC PATH"),"CHECK MODE"))))) -> READY -> /assets/alberto.webp
A10: project-1-video | B10: video | C10: existing_public | D10: /assets/projects/visual-interfaces.mp4 | E10: /assets/projects/visual-interfaces.mp4 | F10: Unity Developer demo video | G10: Unity Developer master video source | H10: TRUE | I10: =IF($A10="","",IF(UPPER($H10)<>"TRUE","",IF($C10="import_local",IF($E10<>"",$E10,""),IF($C10="external_url",$D10,IF(IF($D10<>"",$D10,$E10)<>"",IF($D10<>"",$D10,$E10),""))))) -> /assets/projects/visual-interfaces.mp4 | J10: =IF($A10="","",IF(UPPER($H10)<>"TRUE","Disabled",HYPERLINK("http://127.0.0.1:5173/__dev/asset-source"&"?assetId="&ENCODEURL($A10)&"&sig="&ENCODEURL($B10&"|"&$C10&"|"&$D10&"|"&$E10&"|"&$H10),"Open source"))) -> Open source | K10: =IF($A10="","",IF(OR(UPPER($H10)<>"TRUE",$I10=""),"Unavailable",HYPERLINK("http://127.0.0.1:5173/__dev/asset-resolved"&"?assetId="&ENCODEURL($A10)&"&sig="&ENCODEURL($B10&"|"&$C10&"|"&$D10&"|"&$E10&"|"&$H10),"Open resolved"))) -> Open resolved | L10: Unity Interface Systems video | M10: =IF($A10="","",HYPERLINK("#'ASSET_PREVIEW'!A10","Open preview")) -> Open preview | N10: =IF($A10="","",IF(UPPER($H10)<>"TRUE","DISABLED",IF($C10="external_url",IF(OR(LEFT(LOWER($D10),7)="http://",LEFT(LOWER($D10),8)="https://"),"READY -> "&$I10,"NEEDS HTTP URL"),IF($C10="import_local",IF($D10="","NEEDS SOURCE FILE",IF($E10="","NEEDS TARGET PATH","READY -> "&$I10)),IF($C10="existing_public",IF(IF($D10<>"",$D10,$E10)<>"","READY -> "&$I10,"NEEDS PUBLIC PATH"),"CHECK MODE"))))) -> READY -> /assets/projects/visual-interfaces.mp4
A11: project-1-thumbnail | B11: image | C11: existing_public | D11: /assets/projects/visual-interfaces.png | E11: /assets/projects/visual-interfaces.png | F11: Unity Developer thumbnail | G11: Unity Developer poster image | H11: TRUE | I11: =IF($A11="","",IF(UPPER($H11)<>"TRUE","",IF($C11="import_local",IF($E11<>"",$E11,""),IF($C11="external_url",$D11,IF(IF($D11<>"",$D11,$E11)<>"",IF($D11<>"",$D11,$E11),""))))) -> /assets/projects/visual-interfaces.png | J11: =IF($A11="","",IF(UPPER($H11)<>"TRUE","Disabled",HYPERLINK("http://127.0.0.1:5173/__dev/asset-source"&"?assetId="&ENCODEURL($A11)&"&sig="&ENCODEURL($B11&"|"&$C11&"|"&$D11&"|"&$E11&"|"&$H11),"Open source"))) -> Open source | K11: =IF($A11="","",IF(OR(UPPER($H11)<>"TRUE",$I11=""),"Unavailable",HYPERLINK("http://127.0.0.1:5173/__dev/asset-resolved"&"?assetId="&ENCODEURL($A11)&"&sig="&ENCODEURL($B11&"|"&$C11&"|"&$D11&"|"&$E11&"|"&$H11),"Open resolved"))) -> Open resolved | L11: Unity Interface Systems thumbnail | M11: =IF($A11="","",HYPERLINK("#'ASSET_PREVIEW'!A11","Open preview")) -> Open preview | N11: =IF($A11="","",IF(UPPER($H11)<>"TRUE","DISABLED",IF($C11="external_url",IF(OR(LEFT(LOWER($D11),7)="http://",LEFT(LOWER($D11),8)="https://"),"READY -> "&$I11,"NEEDS HTTP URL"),IF($C11="import_local",IF($D11="","NEEDS SOURCE FILE",IF($E11="","NEEDS TARGET PATH","READY -> "&$I11)),IF($C11="existing_public",IF(IF($D11<>"",$D11,$E11)<>"","READY -> "&$I11,"NEEDS PUBLIC PATH"),"CHECK MODE"))))) -> READY -> /assets/projects/visual-interfaces.png
A12: project-1-icon | B12: icon | C12: existing_public | D12: /assets/projects/unity.webp | E12: /assets/projects/unity.webp | F12: Unity Developer icon | G12: Unity Developer icon asset | H12: TRUE | I12: =IF($A12="","",IF(UPPER($H12)<>"TRUE","",IF($C12="import_local",IF($E12<>"",$E12,""),IF($C12="external_url",$D12,IF(IF($D12<>"",$D12,$E12)<>"",IF($D12<>"",$D12,$E12),""))))) -> /assets/projects/unity.webp | J12: =IF($A12="","",IF(UPPER($H12)<>"TRUE","Disabled",HYPERLINK("http://127.0.0.1:5173/__dev/asset-source"&"?assetId="&ENCODEURL($A12)&"&sig="&ENCODEURL($B12&"|"&$C12&"|"&$D12&"|"&$E12&"|"&$H12),"Open source"))) -> Open source | K12: =IF($A12="","",IF(OR(UPPER($H12)<>"TRUE",$I12=""),"Unavailable",HYPERLINK("http://127.0.0.1:5173/__dev/asset-resolved"&"?assetId="&ENCODEURL($A12)&"&sig="&ENCODEURL($B12&"|"&$C12&"|"&$D12&"|"&$E12&"|"&$H12),"Open resolved"))) -> Open resolved | L12: Unity Interface Systems icon | M12: =IF($A12="","",HYPERLINK("#'ASSET_PREVIEW'!A12","Open preview")) -> Open preview | N12: =IF($A12="","",IF(UPPER($H12)<>"TRUE","DISABLED",IF($C12="external_url",IF(OR(LEFT(LOWER($D12),7)="http://",LEFT(LOWER($D12),8)="https://"),"READY -> "&$I12,"NEEDS HTTP URL"),IF($C12="import_local",IF($D12="","NEEDS SOURCE FILE",IF($E12="","NEEDS TARGET PATH","READY -> "&$I12)),IF($C12="existing_public",IF(IF($D12<>"",$D12,$E12)<>"","READY -> "&$I12,"NEEDS PUBLIC PATH"),"CHECK MODE"))))) -> READY -> /assets/projects/unity.webp
A13: project-2-video | B13: video | C13: existing_public | D13: /assets/projects/zero-touch-ai.mp4 | E13: /assets/projects/zero-touch-ai.mp4 | F13: Smart Inbox Manager demo video | G13: Smart Inbox Manager master video source | H13: TRUE | I13: =IF($A13="","",IF(UPPER($H13)<>"TRUE","",IF($C13="import_local",IF($E13<>"",$E13,""),IF($C13="external_url",$D13,IF(IF($D13<>"",$D13,$E13)<>"",IF($D13<>"",$D13,$E13),""))))) -> /assets/projects/zero-touch-ai.mp4 | J13: =IF($A13="","",IF(UPPER($H13)<>"TRUE","Disabled",HYPERLINK("http://127.0.0.1:5173/__dev/asset-source"&"?assetId="&ENCODEURL($A13)&"&sig="&ENCODEURL($B13&"|"&$C13&"|"&$D13&"|"&$E13&"|"&$H13),"Open source"))) -> Open source | K13: =IF($A13="","",IF(OR(UPPER($H13)<>"TRUE",$I13=""),"Unavailable",HYPERLINK("http://127.0.0.1:5173/__dev/asset-resolved"&"?assetId="&ENCODEURL($A13)&"&sig="&ENCODEURL($B13&"|"&$C13&"|"&$D13&"|"&$E13&"|"&$H13),"Open resolved"))) -> Open resolved | L13: Smart Inbox Manager video | M13: =IF($A13="","",HYPERLINK("#'ASSET_PREVIEW'!A13","Open preview")) -> Open preview | N13: =IF($A13="","",IF(UPPER($H13)<>"TRUE","DISABLED",IF($C13="external_url",IF(OR(LEFT(LOWER($D13),7)="http://",LEFT(LOWER($D13),8)="https://"),"READY -> "&$I13,"NEEDS HTTP URL"),IF($C13="import_local",IF($D13="","NEEDS SOURCE FILE",IF($E13="","NEEDS TARGET PATH","READY -> "&$I13)),IF($C13="existing_public",IF(IF($D13<>"",$D13,$E13)<>"","READY -> "&$I13,"NEEDS PUBLIC PATH"),"CHECK MODE"))))) -> READY -> /assets/projects/zero-touch-ai.mp4
A14: project-2-thumbnail | B14: image | C14: existing_public | D14: /assets/projects/zero-touch-ai.png | E14: /assets/projects/zero-touch-ai.png | F14: Smart Inbox Manager thumbnail | G14: Smart Inbox Manager poster image | H14: TRUE | I14: =IF($A14="","",IF(UPPER($H14)<>"TRUE","",IF($C14="import_local",IF($E14<>"",$E14,""),IF($C14="external_url",$D14,IF(IF($D14<>"",$D14,$E14)<>"",IF($D14<>"",$D14,$E14),""))))) -> /assets/projects/zero-touch-ai.png | J14: =IF($A14="","",IF(UPPER($H14)<>"TRUE","Disabled",HYPERLINK("http://127.0.0.1:5173/__dev/asset-source"&"?assetId="&ENCODEURL($A14)&"&sig="&ENCODEURL($B14&"|"&$C14&"|"&$D14&"|"&$E14&"|"&$H14),"Open source"))) -> Open source | K14: =IF($A14="","",IF(OR(UPPER($H14)<>"TRUE",$I14=""),"Unavailable",HYPERLINK("http://127.0.0.1:5173/__dev/asset-resolved"&"?assetId="&ENCODEURL($A14)&"&sig="&ENCODEURL($B14&"|"&$C14&"|"&$D14&"|"&$E14&"|"&$H14),"Open resolved"))) -> Open resolved | L14: Smart Inbox Manager thumbnail | M14: =IF($A14="","",HYPERLINK("#'ASSET_PREVIEW'!A14","Open preview")) -> Open preview | N14: =IF($A14="","",IF(UPPER($H14)<>"TRUE","DISABLED",IF($C14="external_url",IF(OR(LEFT(LOWER($D14),7)="http://",LEFT(LOWER($D14),8)="https://"),"READY -> "&$I14,"NEEDS HTTP URL"),IF($C14="import_local",IF($D14="","NEEDS SOURCE FILE",IF($E14="","NEEDS TARGET PATH","READY -> "&$I14)),IF($C14="existing_public",IF(IF($D14<>"",$D14,$E14)<>"","READY -> "&$I14,"NEEDS PUBLIC PATH"),"CHECK MODE"))))) -> READY -> /assets/projects/zero-touch-ai.png
A15: project-2-icon | B15: icon | C15: existing_public | D15: /assets/projects/outlook-icon.webp | E15: /assets/projects/outlook-icon.webp | F15: Smart Inbox Manager icon | G15: Smart Inbox Manager icon asset | H15: TRUE | I15: =IF($A15="","",IF(UPPER($H15)<>"TRUE","",IF($C15="import_local",IF($E15<>"",$E15,""),IF($C15="external_url",$D15,IF(IF($D15<>"",$D15,$E15)<>"",IF($D15<>"",$D15,$E15),""))))) -> /assets/projects/outlook-icon.webp | J15: =IF($A15="","",IF(UPPER($H15)<>"TRUE","Disabled",HYPERLINK("http://127.0.0.1:5173/__dev/asset-source"&"?assetId="&ENCODEURL($A15)&"&sig="&ENCODEURL($B15&"|"&$C15&"|"&$D15&"|"&$E15&"|"&$H15),"Open source"))) -> Open source | K15: =IF($A15="","",IF(OR(UPPER($H15)<>"TRUE",$I15=""),"Unavailable",HYPERLINK("http://127.0.0.1:5173/__dev/asset-resolved"&"?assetId="&ENCODEURL($A15)&"&sig="&ENCODEURL($B15&"|"&$C15&"|"&$D15&"|"&$E15&"|"&$H15),"Open resolved"))) -> Open resolved | L15: Smart Inbox Manager icon | M15: =IF($A15="","",HYPERLINK("#'ASSET_PREVIEW'!A15","Open preview")) -> Open preview | N15: =IF($A15="","",IF(UPPER($H15)<>"TRUE","DISABLED",IF($C15="external_url",IF(OR(LEFT(LOWER($D15),7)="http://",LEFT(LOWER($D15),8)="https://"),"READY -> "&$I15,"NEEDS HTTP URL"),IF($C15="import_local",IF($D15="","NEEDS SOURCE FILE",IF($E15="","NEEDS TARGET PATH","READY -> "&$I15)),IF($C15="existing_public",IF(IF($D15<>"",$D15,$E15)<>"","READY -> "&$I15,"NEEDS PUBLIC PATH"),"CHECK MODE"))))) -> READY -> /assets/projects/outlook-icon.webp
A16: project-3-video | B16: video | C16: existing_public | D16: /assets/projects/padel-booking.mp4 | E16: /assets/projects/padel-booking.mp4 | F16: Paddle Booking App demo video | G16: Paddle Booking App master video source | H16: TRUE | I16: =IF($A16="","",IF(UPPER($H16)<>"TRUE","",IF($C16="import_local",IF($E16<>"",$E16,""),IF($C16="external_url",$D16,IF(IF($D16<>"",$D16,$E16)<>"",IF($D16<>"",$D16,$E16),""))))) -> /assets/projects/padel-booking.mp4 | J16: =IF($A16="","",IF(UPPER($H16)<>"TRUE","Disabled",HYPERLINK("http://127.0.0.1:5173/__dev/asset-source"&"?assetId="&ENCODEURL($A16)&"&sig="&ENCODEURL($B16&"|"&$C16&"|"&$D16&"|"&$E16&"|"&$H16),"Open source"))) -> Open source | K16: =IF($A16="","",IF(OR(UPPER($H16)<>"TRUE",$I16=""),"Unavailable",HYPERLINK("http://127.0.0.1:5173/__dev/asset-resolved"&"?assetId="&ENCODEURL($A16)&"&sig="&ENCODEURL($B16&"|"&$C16&"|"&$D16&"|"&$E16&"|"&$H16),"Open resolved"))) -> Open resolved | L16: Padel Booking Platform video | M16: =IF($A16="","",HYPERLINK("#'ASSET_PREVIEW'!A16","Open preview")) -> Open preview | N16: =IF($A16="","",IF(UPPER($H16)<>"TRUE","DISABLED",IF($C16="external_url",IF(OR(LEFT(LOWER($D16),7)="http://",LEFT(LOWER($D16),8)="https://"),"READY -> "&$I16,"NEEDS HTTP URL"),IF($C16="import_local",IF($D16="","NEEDS SOURCE FILE",IF($E16="","NEEDS TARGET PATH","READY -> "&$I16)),IF($C16="existing_public",IF(IF($D16<>"",$D16,$E16)<>"","READY -> "&$I16,"NEEDS PUBLIC PATH"),"CHECK MODE"))))) -> READY -> /assets/projects/padel-booking.mp4
A17: project-3-thumbnail | B17: image | C17: existing_public | D17: /assets/projects/padel-booking.png | E17: /assets/projects/padel-booking.png | F17: Paddle Booking App thumbnail | G17: Paddle Booking App poster image | H17: TRUE | I17: =IF($A17="","",IF(UPPER($H17)<>"TRUE","",IF($C17="import_local",IF($E17<>"",$E17,""),IF($C17="external_url",$D17,IF(IF($D17<>"",$D17,$E17)<>"",IF($D17<>"",$D17,$E17),""))))) -> /assets/projects/padel-booking.png | J17: =IF($A17="","",IF(UPPER($H17)<>"TRUE","Disabled",HYPERLINK("http://127.0.0.1:5173/__dev/asset-source"&"?assetId="&ENCODEURL($A17)&"&sig="&ENCODEURL($B17&"|"&$C17&"|"&$D17&"|"&$E17&"|"&$H17),"Open source"))) -> Open source | K17: =IF($A17="","",IF(OR(UPPER($H17)<>"TRUE",$I17=""),"Unavailable",HYPERLINK("http://127.0.0.1:5173/__dev/asset-resolved"&"?assetId="&ENCODEURL($A17)&"&sig="&ENCODEURL($B17&"|"&$C17&"|"&$D17&"|"&$E17&"|"&$H17),"Open resolved"))) -> Open resolved | L17: Padel Booking Platform thumbnail | M17: =IF($A17="","",HYPERLINK("#'ASSET_PREVIEW'!A17","Open preview")) -> Open preview | N17: =IF($A17="","",IF(UPPER($H17)<>"TRUE","DISABLED",IF($C17="external_url",IF(OR(LEFT(LOWER($D17),7)="http://",LEFT(LOWER($D17),8)="https://"),"READY -> "&$I17,"NEEDS HTTP URL"),IF($C17="import_local",IF($D17="","NEEDS SOURCE FILE",IF($E17="","NEEDS TARGET PATH","READY -> "&$I17)),IF($C17="existing_public",IF(IF($D17<>"",$D17,$E17)<>"","READY -> "&$I17,"NEEDS PUBLIC PATH"),"CHECK MODE"))))) -> READY -> /assets/projects/padel-booking.png
A18: project-3-icon | B18: icon | C18: existing_public | D18: /assets/projects/padel-booking-logo.png | E18: /assets/projects/padel-booking-logo.png | F18: Paddle Booking App icon | G18: Paddle Booking App icon asset | H18: TRUE | I18: =IF($A18="","",IF(UPPER($H18)<>"TRUE","",IF($C18="import_local",IF($E18<>"",$E18,""),IF($C18="external_url",$D18,IF(IF($D18<>"",$D18,$E18)<>"",IF($D18<>"",$D18,$E18),""))))) -> /assets/projects/padel-booking-logo.png | J18: =IF($A18="","",IF(UPPER($H18)<>"TRUE","Disabled",HYPERLINK("http://127.0.0.1:5173/__dev/asset-source"&"?assetId="&ENCODEURL($A18)&"&sig="&ENCODEURL($B18&"|"&$C18&"|"&$D18&"|"&$E18&"|"&$H18),"Open source"))) -> Open source | K18: =IF($A18="","",IF(OR(UPPER($H18)<>"TRUE",$I18=""),"Unavailable",HYPERLINK("http://127.0.0.1:5173/__dev/asset-resolved"&"?assetId="&ENCODEURL($A18)&"&sig="&ENCODEURL($B18&"|"&$C18&"|"&$D18&"|"&$E18&"|"&$H18),"Open resolved"))) -> Open resolved | L18: Padel Booking Platform icon | M18: =IF($A18="","",HYPERLINK("#'ASSET_PREVIEW'!A18","Open preview")) -> Open preview | N18: =IF($A18="","",IF(UPPER($H18)<>"TRUE","DISABLED",IF($C18="external_url",IF(OR(LEFT(LOWER($D18),7)="http://",LEFT(LOWER($D18),8)="https://"),"READY -> "&$I18,"NEEDS HTTP URL"),IF($C18="import_local",IF($D18="","NEEDS SOURCE FILE",IF($E18="","NEEDS TARGET PATH","READY -> "&$I18)),IF($C18="existing_public",IF(IF($D18<>"",$D18,$E18)<>"","READY -> "&$I18,"NEEDS PUBLIC PATH"),"CHECK MODE"))))) -> READY -> /assets/projects/padel-booking-logo.png
A19: project-4-video | B19: video | C19: existing_public | D19: /assets/projects/twitch-live.mp4 | E19: /assets/projects/twitch-live.mp4 | F19: Twitch Live Analytics demo video | G19: Twitch Live Analytics master video source | H19: TRUE | I19: =IF($A19="","",IF(UPPER($H19)<>"TRUE","",IF($C19="import_local",IF($E19<>"",$E19,""),IF($C19="external_url",$D19,IF(IF($D19<>"",$D19,$E19)<>"",IF($D19<>"",$D19,$E19),""))))) -> /assets/projects/twitch-live.mp4 | J19: =IF($A19="","",IF(UPPER($H19)<>"TRUE","Disabled",HYPERLINK("http://127.0.0.1:5173/__dev/asset-source"&"?assetId="&ENCODEURL($A19)&"&sig="&ENCODEURL($B19&"|"&$C19&"|"&$D19&"|"&$E19&"|"&$H19),"Open source"))) -> Open source | K19: =IF($A19="","",IF(OR(UPPER($H19)<>"TRUE",$I19=""),"Unavailable",HYPERLINK("http://127.0.0.1:5173/__dev/asset-resolved"&"?assetId="&ENCODEURL($A19)&"&sig="&ENCODEURL($B19&"|"&$C19&"|"&$D19&"|"&$E19&"|"&$H19),"Open resolved"))) -> Open resolved | L19: Twitch Live Analytics video | M19: =IF($A19="","",HYPERLINK("#'ASSET_PREVIEW'!A19","Open preview")) -> Open preview | N19: =IF($A19="","",IF(UPPER($H19)<>"TRUE","DISABLED",IF($C19="external_url",IF(OR(LEFT(LOWER($D19),7)="http://",LEFT(LOWER($D19),8)="https://"),"READY -> "&$I19,"NEEDS HTTP URL"),IF($C19="import_local",IF($D19="","NEEDS SOURCE FILE",IF($E19="","NEEDS TARGET PATH","READY -> "&$I19)),IF($C19="existing_public",IF(IF($D19<>"",$D19,$E19)<>"","READY -> "&$I19,"NEEDS PUBLIC PATH"),"CHECK MODE"))))) -> READY -> /assets/projects/twitch-live.mp4
A20: project-4-thumbnail | B20: image | C20: existing_public | D20: /assets/projects/twitch-live.png | E20: /assets/projects/twitch-live.png | F20: Twitch Live Analytics thumbnail | G20: Twitch Live Analytics poster image | H20: TRUE | I20: =IF($A20="","",IF(UPPER($H20)<>"TRUE","",IF($C20="import_local",IF($E20<>"",$E20,""),IF($C20="external_url",$D20,IF(IF($D20<>"",$D20,$E20)<>"",IF($D20<>"",$D20,$E20),""))))) -> /assets/projects/twitch-live.png | J20: =IF($A20="","",IF(UPPER($H20)<>"TRUE","Disabled",HYPERLINK("http://127.0.0.1:5173/__dev/asset-source"&"?assetId="&ENCODEURL($A20)&"&sig="&ENCODEURL($B20&"|"&$C20&"|"&$D20&"|"&$E20&"|"&$H20),"Open source"))) -> Open source | K20: =IF($A20="","",IF(OR(UPPER($H20)<>"TRUE",$I20=""),"Unavailable",HYPERLINK("http://127.0.0.1:5173/__dev/asset-resolved"&"?assetId="&ENCODEURL($A20)&"&sig="&ENCODEURL($B20&"|"&$C20&"|"&$D20&"|"&$E20&"|"&$H20),"Open resolved"))) -> Open resolved | L20: Twitch Live Analytics thumbnail | M20: =IF($A20="","",HYPERLINK("#'ASSET_PREVIEW'!A20","Open preview")) -> Open preview | N20: =IF($A20="","",IF(UPPER($H20)<>"TRUE","DISABLED",IF($C20="external_url",IF(OR(LEFT(LOWER($D20),7)="http://",LEFT(LOWER($D20),8)="https://"),"READY -> "&$I20,"NEEDS HTTP URL"),IF($C20="import_local",IF($D20="","NEEDS SOURCE FILE",IF($E20="","NEEDS TARGET PATH","READY -> "&$I20)),IF($C20="existing_public",IF(IF($D20<>"",$D20,$E20)<>"","READY -> "&$I20,"NEEDS PUBLIC PATH"),"CHECK MODE"))))) -> READY -> /assets/projects/twitch-live.png
A21: project-4-icon | B21: icon | C21: existing_public | D21: /assets/projects/twitch-icon.webp | E21: /assets/projects/twitch-icon.webp | F21: Twitch Live Analytics icon | G21: Twitch Live Analytics icon asset | H21: TRUE | I21: =IF($A21="","",IF(UPPER($H21)<>"TRUE","",IF($C21="import_local",IF($E21<>"",$E21,""),IF($C21="external_url",$D21,IF(IF($D21<>"",$D21,$E21)<>"",IF($D21<>"",$D21,$E21),""))))) -> /assets/projects/twitch-icon.webp | J21: =IF($A21="","",IF(UPPER($H21)<>"TRUE","Disabled",HYPERLINK("http://127.0.0.1:5173/__dev/asset-source"&"?assetId="&ENCODEURL($A21)&"&sig="&ENCODEURL($B21&"|"&$C21&"|"&$D21&"|"&$E21&"|"&$H21),"Open source"))) -> Open source | K21: =IF($A21="","",IF(OR(UPPER($H21)<>"TRUE",$I21=""),"Unavailable",HYPERLINK("http://127.0.0.1:5173/__dev/asset-resolved"&"?assetId="&ENCODEURL($A21)&"&sig="&ENCODEURL($B21&"|"&$C21&"|"&$D21&"|"&$E21&"|"&$H21),"Open resolved"))) -> Open resolved | L21: Twitch Live Analytics icon | M21: =IF($A21="","",HYPERLINK("#'ASSET_PREVIEW'!A21","Open preview")) -> Open preview | N21: =IF($A21="","",IF(UPPER($H21)<>"TRUE","DISABLED",IF($C21="external_url",IF(OR(LEFT(LOWER($D21),7)="http://",LEFT(LOWER($D21),8)="https://"),"READY -> "&$I21,"NEEDS HTTP URL"),IF($C21="import_local",IF($D21="","NEEDS SOURCE FILE",IF($E21="","NEEDS TARGET PATH","READY -> "&$I21)),IF($C21="existing_public",IF(IF($D21<>"",$D21,$E21)<>"","READY -> "&$I21,"NEEDS PUBLIC PATH"),"CHECK MODE"))))) -> READY -> /assets/projects/twitch-icon.webp
A22: project-5-video | B22: video | C22: existing_public | D22: /assets/projects/usb-extraction.mp4 | E22: /assets/projects/usb-extraction.mp4 | F22: USB Exfiltration demo video | G22: USB Exfiltration master video source | H22: TRUE | I22: =IF($A22="","",IF(UPPER($H22)<>"TRUE","",IF($C22="import_local",IF($E22<>"",$E22,""),IF($C22="external_url",$D22,IF(IF($D22<>"",$D22,$E22)<>"",IF($D22<>"",$D22,$E22),""))))) -> /assets/projects/usb-extraction.mp4 | J22: =IF($A22="","",IF(UPPER($H22)<>"TRUE","Disabled",HYPERLINK("http://127.0.0.1:5173/__dev/asset-source"&"?assetId="&ENCODEURL($A22)&"&sig="&ENCODEURL($B22&"|"&$C22&"|"&$D22&"|"&$E22&"|"&$H22),"Open source"))) -> Open source | K22: =IF($A22="","",IF(OR(UPPER($H22)<>"TRUE",$I22=""),"Unavailable",HYPERLINK("http://127.0.0.1:5173/__dev/asset-resolved"&"?assetId="&ENCODEURL($A22)&"&sig="&ENCODEURL($B22&"|"&$C22&"|"&$D22&"|"&$E22&"|"&$H22),"Open resolved"))) -> Open resolved | L22: USB Exfiltration Tool video | M22: =IF($A22="","",HYPERLINK("#'ASSET_PREVIEW'!A22","Open preview")) -> Open preview | N22: =IF($A22="","",IF(UPPER($H22)<>"TRUE","DISABLED",IF($C22="external_url",IF(OR(LEFT(LOWER($D22),7)="http://",LEFT(LOWER($D22),8)="https://"),"READY -> "&$I22,"NEEDS HTTP URL"),IF($C22="import_local",IF($D22="","NEEDS SOURCE FILE",IF($E22="","NEEDS TARGET PATH","READY -> "&$I22)),IF($C22="existing_public",IF(IF($D22<>"",$D22,$E22)<>"","READY -> "&$I22,"NEEDS PUBLIC PATH"),"CHECK MODE"))))) -> READY -> /assets/projects/usb-extraction.mp4
A23: project-5-thumbnail | B23: image | C23: existing_public | D23: /assets/projects/usb-extraction.png | E23: /assets/projects/usb-extraction.png | F23: USB Exfiltration thumbnail | G23: USB Exfiltration poster image | H23: TRUE | I23: =IF($A23="","",IF(UPPER($H23)<>"TRUE","",IF($C23="import_local",IF($E23<>"",$E23,""),IF($C23="external_url",$D23,IF(IF($D23<>"",$D23,$E23)<>"",IF($D23<>"",$D23,$E23),""))))) -> /assets/projects/usb-extraction.png | J23: =IF($A23="","",IF(UPPER($H23)<>"TRUE","Disabled",HYPERLINK("http://127.0.0.1:5173/__dev/asset-source"&"?assetId="&ENCODEURL($A23)&"&sig="&ENCODEURL($B23&"|"&$C23&"|"&$D23&"|"&$E23&"|"&$H23),"Open source"))) -> Open source | K23: =IF($A23="","",IF(OR(UPPER($H23)<>"TRUE",$I23=""),"Unavailable",HYPERLINK("http://127.0.0.1:5173/__dev/asset-resolved"&"?assetId="&ENCODEURL($A23)&"&sig="&ENCODEURL($B23&"|"&$C23&"|"&$D23&"|"&$E23&"|"&$H23),"Open resolved"))) -> Open resolved | L23: USB Exfiltration Tool thumbnail | M23: =IF($A23="","",HYPERLINK("#'ASSET_PREVIEW'!A23","Open preview")) -> Open preview | N23: =IF($A23="","",IF(UPPER($H23)<>"TRUE","DISABLED",IF($C23="external_url",IF(OR(LEFT(LOWER($D23),7)="http://",LEFT(LOWER($D23),8)="https://"),"READY -> "&$I23,"NEEDS HTTP URL"),IF($C23="import_local",IF($D23="","NEEDS SOURCE FILE",IF($E23="","NEEDS TARGET PATH","READY -> "&$I23)),IF($C23="existing_public",IF(IF($D23<>"",$D23,$E23)<>"","READY -> "&$I23,"NEEDS PUBLIC PATH"),"CHECK MODE"))))) -> READY -> /assets/projects/usb-extraction.png
A24: project-5-icon | B24: icon | C24: existing_public | D24: /assets/projects/terminal.ico | E24: /assets/projects/terminal.ico | F24: USB Exfiltration icon | G24: USB Exfiltration icon asset | H24: TRUE | I24: =IF($A24="","",IF(UPPER($H24)<>"TRUE","",IF($C24="import_local",IF($E24<>"",$E24,""),IF($C24="external_url",$D24,IF(IF($D24<>"",$D24,$E24)<>"",IF($D24<>"",$D24,$E24),""))))) -> /assets/projects/terminal.ico | J24: =IF($A24="","",IF(UPPER($H24)<>"TRUE","Disabled",HYPERLINK("http://127.0.0.1:5173/__dev/asset-source"&"?assetId="&ENCODEURL($A24)&"&sig="&ENCODEURL($B24&"|"&$C24&"|"&$D24&"|"&$E24&"|"&$H24),"Open source"))) -> Open source | K24: =IF($A24="","",IF(OR(UPPER($H24)<>"TRUE",$I24=""),"Unavailable",HYPERLINK("http://127.0.0.1:5173/__dev/asset-resolved"&"?assetId="&ENCODEURL($A24)&"&sig="&ENCODEURL($B24&"|"&$C24&"|"&$D24&"|"&$E24&"|"&$H24),"Open resolved"))) -> Open resolved | L24: USB Exfiltration Tool icon | M24: =IF($A24="","",HYPERLINK("#'ASSET_PREVIEW'!A24","Open preview")) -> Open preview | N24: =IF($A24="","",IF(UPPER($H24)<>"TRUE","DISABLED",IF($C24="external_url",IF(OR(LEFT(LOWER($D24),7)="http://",LEFT(LOWER($D24),8)="https://"),"READY -> "&$I24,"NEEDS HTTP URL"),IF($C24="import_local",IF($D24="","NEEDS SOURCE FILE",IF($E24="","NEEDS TARGET PATH","READY -> "&$I24)),IF($C24="existing_public",IF(IF($D24<>"",$D24,$E24)<>"","READY -> "&$I24,"NEEDS PUBLIC PATH"),"CHECK MODE"))))) -> READY -> /assets/projects/terminal.ico
A25: testimonial-client3 | B25: image | C25: existing_public | D25: /assets/testimonials/client3.png | E25: /assets/testimonials/client3.png | F25: Anonymized Fiverr client avatar | G25: Avatar used by anonymized Fiverr testimonials | H25: TRUE | I25: =IF($A25="","",IF(UPPER($H25)<>"TRUE","",IF($C25="import_local",IF($E25<>"",$E25,""),IF($C25="external_url",$D25,IF(IF($D25<>"",$D25,$E25)<>"",IF($D25<>"",$D25,$E25),""))))) -> /assets/testimonials/client3.png | J25: =IF($A25="","",IF(UPPER($H25)<>"TRUE","Disabled",HYPERLINK("http://127.0.0.1:5173/__dev/asset-source"&"?assetId="&ENCODEURL($A25)&"&sig="&ENCODEURL($B25&"|"&$C25&"|"&$D25&"|"&$E25&"|"&$H25),"Open source"))) -> Open source | K25: =IF($A25="","",IF(OR(UPPER($H25)<>"TRUE",$I25=""),"Unavailable",HYPERLINK("http://127.0.0.1:5173/__dev/asset-resolved"&"?assetId="&ENCODEURL($A25)&"&sig="&ENCODEURL($B25&"|"&$C25&"|"&$D25&"|"&$E25&"|"&$H25),"Open resolved"))) -> Open resolved | L25: automation-outstanding-work avatar | M25: =IF($A25="","",HYPERLINK("#'ASSET_PREVIEW'!A25","Open preview")) -> Open preview | N25: =IF($A25="","",IF(UPPER($H25)<>"TRUE","DISABLED",IF($C25="external_url",IF(OR(LEFT(LOWER($D25),7)="http://",LEFT(LOWER($D25),8)="https://"),"READY -> "&$I25,"NEEDS HTTP URL"),IF($C25="import_local",IF($D25="","NEEDS SOURCE FILE",IF($E25="","NEEDS TARGET PATH","READY -> "&$I25)),IF($C25="existing_public",IF(IF($D25<>"",$D25,$E25)<>"","READY -> "&$I25,"NEEDS PUBLIC PATH"),"CHECK MODE"))))) -> READY -> /assets/testimonials/client3.png
A26: testimonial-client2 | B26: image | C26: existing_public | D26: /assets/testimonials/client2.png | E26: /assets/testimonials/client2.png | F26: Anonymized Fiverr client avatar | G26: Avatar used by anonymized Fiverr testimonials | H26: TRUE | I26: =IF($A26="","",IF(UPPER($H26)<>"TRUE","",IF($C26="import_local",IF($E26<>"",$E26,""),IF($C26="external_url",$D26,IF(IF($D26<>"",$D26,$E26)<>"",IF($D26<>"",$D26,$E26),""))))) -> /assets/testimonials/client2.png | J26: =IF($A26="","",IF(UPPER($H26)<>"TRUE","Disabled",HYPERLINK("http://127.0.0.1:5173/__dev/asset-source"&"?assetId="&ENCODEURL($A26)&"&sig="&ENCODEURL($B26&"|"&$C26&"|"&$D26&"|"&$E26&"|"&$H26),"Open source"))) -> Open source | K26: =IF($A26="","",IF(OR(UPPER($H26)<>"TRUE",$I26=""),"Unavailable",HYPERLINK("http://127.0.0.1:5173/__dev/asset-resolved"&"?assetId="&ENCODEURL($A26)&"&sig="&ENCODEURL($B26&"|"&$C26&"|"&$D26&"|"&$E26&"|"&$H26),"Open resolved"))) -> Open resolved | L26: unity-great-work avatar | M26: =IF($A26="","",HYPERLINK("#'ASSET_PREVIEW'!A26","Open preview")) -> Open preview | N26: =IF($A26="","",IF(UPPER($H26)<>"TRUE","DISABLED",IF($C26="external_url",IF(OR(LEFT(LOWER($D26),7)="http://",LEFT(LOWER($D26),8)="https://"),"READY -> "&$I26,"NEEDS HTTP URL"),IF($C26="import_local",IF($D26="","NEEDS SOURCE FILE",IF($E26="","NEEDS TARGET PATH","READY -> "&$I26)),IF($C26="existing_public",IF(IF($D26<>"",$D26,$E26)<>"","READY -> "&$I26,"NEEDS PUBLIC PATH"),"CHECK MODE"))))) -> READY -> /assets/testimonials/client2.png
A27: testimonial-client1 | B27: image | C27: existing_public | D27: /assets/testimonials/client1.png | E27: /assets/testimonials/client1.png | F27: Anonymized Fiverr client avatar | G27: Avatar used by anonymized Fiverr testimonials | H27: TRUE | I27: =IF($A27="","",IF(UPPER($H27)<>"TRUE","",IF($C27="import_local",IF($E27<>"",$E27,""),IF($C27="external_url",$D27,IF(IF($D27<>"",$D27,$E27)<>"",IF($D27<>"",$D27,$E27),""))))) -> /assets/testimonials/client1.png | J27: =IF($A27="","",IF(UPPER($H27)<>"TRUE","Disabled",HYPERLINK("http://127.0.0.1:5173/__dev/asset-source"&"?assetId="&ENCODEURL($A27)&"&sig="&ENCODEURL($B27&"|"&$C27&"|"&$D27&"|"&$E27&"|"&$H27),"Open source"))) -> Open source | K27: =IF($A27="","",IF(OR(UPPER($H27)<>"TRUE",$I27=""),"Unavailable",HYPERLINK("http://127.0.0.1:5173/__dev/asset-resolved"&"?assetId="&ENCODEURL($A27)&"&sig="&ENCODEURL($B27&"|"&$C27&"|"&$D27&"|"&$E27&"|"&$H27),"Open resolved"))) -> Open resolved | L27: automation-nice-guy avatar | M27: =IF($A27="","",HYPERLINK("#'ASSET_PREVIEW'!A27","Open preview")) -> Open preview | N27: =IF($A27="","",IF(UPPER($H27)<>"TRUE","DISABLED",IF($C27="external_url",IF(OR(LEFT(LOWER($D27),7)="http://",LEFT(LOWER($D27),8)="https://"),"READY -> "&$I27,"NEEDS HTTP URL"),IF($C27="import_local",IF($D27="","NEEDS SOURCE FILE",IF($E27="","NEEDS TARGET PATH","READY -> "&$I27)),IF($C27="existing_public",IF(IF($D27<>"",$D27,$E27)<>"","READY -> "&$I27,"NEEDS PUBLIC PATH"),"CHECK MODE"))))) -> READY -> /assets/testimonials/client1.png
A28: testimonial-client4 | B28: image | C28: existing_public | D28: /assets/testimonials/client4.png | E28: /assets/testimonials/client4.png | F28: Anonymized Fiverr client avatar | G28: Avatar used by anonymized Fiverr testimonials | H28: TRUE | I28: =IF($A28="","",IF(UPPER($H28)<>"TRUE","",IF($C28="import_local",IF($E28<>"",$E28,""),IF($C28="external_url",$D28,IF(IF($D28<>"",$D28,$E28)<>"",IF($D28<>"",$D28,$E28),""))))) -> /assets/testimonials/client4.png | J28: =IF($A28="","",IF(UPPER($H28)<>"TRUE","Disabled",HYPERLINK("http://127.0.0.1:5173/__dev/asset-source"&"?assetId="&ENCODEURL($A28)&"&sig="&ENCODEURL($B28&"|"&$C28&"|"&$D28&"|"&$E28&"|"&$H28),"Open source"))) -> Open source | K28: =IF($A28="","",IF(OR(UPPER($H28)<>"TRUE",$I28=""),"Unavailable",HYPERLINK("http://127.0.0.1:5173/__dev/asset-resolved"&"?assetId="&ENCODEURL($A28)&"&sig="&ENCODEURL($B28&"|"&$C28&"|"&$D28&"|"&$E28&"|"&$H28),"Open resolved"))) -> Open resolved | L28: automation-wonderful-details avatar | M28: =IF($A28="","",HYPERLINK("#'ASSET_PREVIEW'!A28","Open preview")) -> Open preview | N28: =IF($A28="","",IF(UPPER($H28)<>"TRUE","DISABLED",IF($C28="external_url",IF(OR(LEFT(LOWER($D28),7)="http://",LEFT(LOWER($D28),8)="https://"),"READY -> "&$I28,"NEEDS HTTP URL"),IF($C28="import_local",IF($D28="","NEEDS SOURCE FILE",IF($E28="","NEEDS TARGET PATH","READY -> "&$I28)),IF($C28="existing_public",IF(IF($D28<>"",$D28,$E28)<>"","READY -> "&$I28,"NEEDS PUBLIC PATH"),"CHECK MODE"))))) -> READY -> /assets/testimonials/client4.png
A29: testimonial-client5 | B29: image | C29: existing_public | D29: /assets/testimonials/client5.jpg | E29: /assets/testimonials/client5.jpg | F29: Anonymized Fiverr client avatar | G29: Synthetic avatar used by anonymized Fiverr testimonials | H29: TRUE | I29: =IF($A29="","",IF(UPPER($H29)<>"TRUE","",IF($C29="import_local",IF($E29<>"",$E29,""),IF($C29="external_url",$D29,IF(IF($D29<>"",$D29,$E29)<>"",IF($D29<>"",$D29,$E29),""))))) -> /assets/testimonials/client5.jpg | J29: =IF($A29="","",IF(UPPER($H29)<>"TRUE","Disabled",HYPERLINK("http://127.0.0.1:5173/__dev/asset-source"&"?assetId="&ENCODEURL($A29)&"&sig="&ENCODEURL($B29&"|"&$C29&"|"&$D29&"|"&$E29&"|"&$H29),"Open source"))) -> Open source | K29: =IF($A29="","",IF(OR(UPPER($H29)<>"TRUE",$I29=""),"Unavailable",HYPERLINK("http://127.0.0.1:5173/__dev/asset-resolved"&"?assetId="&ENCODEURL($A29)&"&sig="&ENCODEURL($B29&"|"&$C29&"|"&$D29&"|"&$E29&"|"&$H29),"Open resolved"))) -> Open resolved | L29: automation-seo-detail avatar | M29: =IF($A29="","",HYPERLINK("#'ASSET_PREVIEW'!A29","Open preview")) -> Open preview | N29: =IF($A29="","",IF(UPPER($H29)<>"TRUE","DISABLED",IF($C29="external_url",IF(OR(LEFT(LOWER($D29),7)="http://",LEFT(LOWER($D29),8)="https://"),"READY -> "&$I29,"NEEDS HTTP URL"),IF($C29="import_local",IF($D29="","NEEDS SOURCE FILE",IF($E29="","NEEDS TARGET PATH","READY -> "&$I29)),IF($C29="existing_public",IF(IF($D29<>"",$D29,$E29)<>"","READY -> "&$I29,"NEEDS PUBLIC PATH"),"CHECK MODE"))))) -> READY -> /assets/testimonials/client5.jpg
A30: testimonial-client6 | B30: image | C30: existing_public | D30: /assets/testimonials/client6.jpg | E30: /assets/testimonials/client6.jpg | F30: Anonymized Fiverr client avatar | G30: Synthetic avatar used by anonymized Fiverr testimonials | H30: TRUE | I30: =IF($A30="","",IF(UPPER($H30)<>"TRUE","",IF($C30="import_local",IF($E30<>"",$E30,""),IF($C30="external_url",$D30,IF(IF($D30<>"",$D30,$E30)<>"",IF($D30<>"",$D30,$E30),""))))) -> /assets/testimonials/client6.jpg | J30: =IF($A30="","",IF(UPPER($H30)<>"TRUE","Disabled",HYPERLINK("http://127.0.0.1:5173/__dev/asset-source"&"?assetId="&ENCODEURL($A30)&"&sig="&ENCODEURL($B30&"|"&$C30&"|"&$D30&"|"&$E30&"|"&$H30),"Open source"))) -> Open source | K30: =IF($A30="","",IF(OR(UPPER($H30)<>"TRUE",$I30=""),"Unavailable",HYPERLINK("http://127.0.0.1:5173/__dev/asset-resolved"&"?assetId="&ENCODEURL($A30)&"&sig="&ENCODEURL($B30&"|"&$C30&"|"&$D30&"|"&$E30&"|"&$H30),"Open resolved"))) -> Open resolved | L30: automation-fast-turnaround avatar | M30: =IF($A30="","",HYPERLINK("#'ASSET_PREVIEW'!A30","Open preview")) -> Open preview | N30: =IF($A30="","",IF(UPPER($H30)<>"TRUE","DISABLED",IF($C30="external_url",IF(OR(LEFT(LOWER($D30),7)="http://",LEFT(LOWER($D30),8)="https://"),"READY -> "&$I30,"NEEDS HTTP URL"),IF($C30="import_local",IF($D30="","NEEDS SOURCE FILE",IF($E30="","NEEDS TARGET PATH","READY -> "&$I30)),IF($C30="existing_public",IF(IF($D30<>"",$D30,$E30)<>"","READY -> "&$I30,"NEEDS PUBLIC PATH"),"CHECK MODE"))))) -> READY -> /assets/testimonials/client6.jpg
A31: testimonial-client7 | B31: image | C31: existing_public | D31: /assets/testimonials/client7.jpg | E31: /assets/testimonials/client7.jpg | F31: Anonymized Fiverr client avatar | G31: Synthetic avatar used by anonymized Fiverr testimonials | H31: TRUE | I31: =IF($A31="","",IF(UPPER($H31)<>"TRUE","",IF($C31="import_local",IF($E31<>"",$E31,""),IF($C31="external_url",$D31,IF(IF($D31<>"",$D31,$E31)<>"",IF($D31<>"",$D31,$E31),""))))) -> /assets/testimonials/client7.jpg | J31: =IF($A31="","",IF(UPPER($H31)<>"TRUE","Disabled",HYPERLINK("http://127.0.0.1:5173/__dev/asset-source"&"?assetId="&ENCODEURL($A31)&"&sig="&ENCODEURL($B31&"|"&$C31&"|"&$D31&"|"&$E31&"|"&$H31),"Open source"))) -> Open source | K31: =IF($A31="","",IF(OR(UPPER($H31)<>"TRUE",$I31=""),"Unavailable",HYPERLINK("http://127.0.0.1:5173/__dev/asset-resolved"&"?assetId="&ENCODEURL($A31)&"&sig="&ENCODEURL($B31&"|"&$C31&"|"&$D31&"|"&$E31&"|"&$H31),"Open resolved"))) -> Open resolved | L31: automation-vigor avatar | M31: =IF($A31="","",HYPERLINK("#'ASSET_PREVIEW'!A31","Open preview")) -> Open preview | N31: =IF($A31="","",IF(UPPER($H31)<>"TRUE","DISABLED",IF($C31="external_url",IF(OR(LEFT(LOWER($D31),7)="http://",LEFT(LOWER($D31),8)="https://"),"READY -> "&$I31,"NEEDS HTTP URL"),IF($C31="import_local",IF($D31="","NEEDS SOURCE FILE",IF($E31="","NEEDS TARGET PATH","READY -> "&$I31)),IF($C31="existing_public",IF(IF($D31<>"",$D31,$E31)<>"","READY -> "&$I31,"NEEDS PUBLIC PATH"),"CHECK MODE"))))) -> READY -> /assets/testimonials/client7.jpg
A32: testimonial-client8 | B32: image | C32: existing_public | D32: /assets/testimonials/client8.jpg | E32: /assets/testimonials/client8.jpg | F32: Anonymized Fiverr client avatar | G32: Synthetic avatar used by anonymized Fiverr testimonials | H32: TRUE | I32: =IF($A32="","",IF(UPPER($H32)<>"TRUE","",IF($C32="import_local",IF($E32<>"",$E32,""),IF($C32="external_url",$D32,IF(IF($D32<>"",$D32,$E32)<>"",IF($D32<>"",$D32,$E32),""))))) -> /assets/testimonials/client8.jpg | J32: =IF($A32="","",IF(UPPER($H32)<>"TRUE","Disabled",HYPERLINK("http://127.0.0.1:5173/__dev/asset-source"&"?assetId="&ENCODEURL($A32)&"&sig="&ENCODEURL($B32&"|"&$C32&"|"&$D32&"|"&$E32&"|"&$H32),"Open source"))) -> Open source | K32: =IF($A32="","",IF(OR(UPPER($H32)<>"TRUE",$I32=""),"Unavailable",HYPERLINK("http://127.0.0.1:5173/__dev/asset-resolved"&"?assetId="&ENCODEURL($A32)&"&sig="&ENCODEURL($B32&"|"&$C32&"|"&$D32&"|"&$E32&"|"&$H32),"Open resolved"))) -> Open resolved | L32: 2 refs | unity-progress-communication avatar | M32: =IF($A32="","",HYPERLINK("#'ASSET_PREVIEW'!A32","Open preview")) -> Open preview | N32: =IF($A32="","",IF(UPPER($H32)<>"TRUE","DISABLED",IF($C32="external_url",IF(OR(LEFT(LOWER($D32),7)="http://",LEFT(LOWER($D32),8)="https://"),"READY -> "&$I32,"NEEDS HTTP URL"),IF($C32="import_local",IF($D32="","NEEDS SOURCE FILE",IF($E32="","NEEDS TARGET PATH","READY -> "&$I32)),IF($C32="existing_public",IF(IF($D32<>"",$D32,$E32)<>"","READY -> "&$I32,"NEEDS PUBLIC PATH"),"CHECK MODE"))))) -> READY -> /assets/testimonials/client8.jpg
